<?xml version="1.0"?>
<robot xmlns:xacro="http://www.ros.org/wiki/xacro" name="wheel">
    <xacro:include filename="inertial.xacro"/>

    <material name="wheel_color">
        <color rgba="1 0.3 0.1 1"/>
    </material>

    <xacro:macro name="mecanum_wheel" params="prefix parent *origin">

        <joint name="${prefix}_wheel_joint" type="continuous">
            <parent link="${parent}"/>
            <child link="${prefix}_wheel_link"/>
            <xacro:insert_block name="origin"/>
            <axis xyz="0 0 1"/>
        </joint>


        <link name="${prefix}_wheel_link">
            <visual>
                <geometry>
                    <cylinder radius="0.05" length="0.04"/>
                </geometry>
                <material name="wheel_color"/>
            </visual>
            <collision>
                <geometry>
                    <cylinder radius="0.05" length="0.04"/>
                </geometry>
            </collision>
            <xacro:inertial_cylinder mass="0.1" length="0.04" radius="0.05">
                <origin xyz="0 0 0" rpy="0 0 0"/>
            </xacro:inertial_cylinder>
        </link>

        <gazebo reference="${prefix}_wheel_link">
            <material>Gazebo/Blue</material>
        </gazebo>
    
    </xacro:macro>

</robot>